File: example/example.ras
*RAS_DATA_START
*RAS_HEADER_START
*DISP_FMT_X "%.2f"
*DISP_FMT_Y "%.0f"
*DISP_FULLSCALE "56070.0000000000"
*DISP_LINE_COLOR "255.0000000000"
*DISP_LINE_STYLE "0.0000000000"
*DISP_LINE_WIDTH "0.2500000000"
*DISP_NOTE "測定データ-68"
*DISP_OFFSET_Y "0.0000000000"
*DISP_PEAKSEARCH_UNIT_Y "cps"
*DISP_RANGE_BOTTOM "0.0000000000"
*DISP_RANGE_LEFT "10.0000000000"
*DISP_RANGE_LOGCUTOFF "0.0100000000"
*DISP_RANGE_RIGHT "90.0000000000"
*DISP_RANGE_TOP "56070.0000000000"
*DISP_SCALE_MODE_Y "0.0000000000"
*DISP_TAB_NAME "2θ/θ"
*DISP_TITLE_Y "強度"
*DISP_UNIT_Y "cps"
*DISP_WINDOW_NAME "MSG_MACROENGINE"
*FILE_COMMENT " "
*FILE_MD5 ""
*FILE_MEMO " "
*FILE_OPERATOR "User1"
*FILE_PART_ID "MEAS_KHP2_00068"
*FILE_SAMPLE " "
*FILE_TYPE "RAS_RAW"
*FILE_USERGROUP "システムマネージャ"
*FILE_VERSION "1.0000000000"
*HW_ATTACHMENT_ID "ATT0025"
*HW_ATTACHMENT_NAME "標準|Standard"
*HW_COUNTER_ID-0 "CUT0025"
*HW_COUNTER_ID-1 "CUT0020"
*HW_COUNTER_ID-2 "CUT0020"
*HW_COUNTER_ID-3 "CSL0021"
*HW_COUNTER_ID-4 "CMC0021"
*HW_COUNTER_NAME-0 "D/teX Ultra|D/teX Ultra"
*HW_COUNTER_NAME-1 "None|None"
*HW_COUNTER_NAME-2 "None|None"
*HW_COUNTER_NAME-3 "BBM|BBM"
*HW_COUNTER_NAME-4 "検出器モノクロメータ|Detector monochromator"
*HW_COUNTER_SELECT_NAME "D/teX Ultra|D/teX Ultra"
*HW_GONIOMETER_ID "GON0023"
*HW_GONIOMETER_NAME "SmartLab|SmartLab"
*HW_GONIOMETER_RADIUS-0 "90.0"
*HW_GONIOMETER_RADIUS-1 "114.0"
*HW_GONIOMETER_RADIUS-2 "190.0"
*HW_GONIOMETER_RADIUS-3 "300.0"
*HW_GONIOMETER_RADIUS-4 "183.0"
*HW_GONIOMETER_RADIUS-5 "259.0"
*HW_GONIOMETER_RADIUS-6 "76.0"
*HW_GONIOMETER_RADIUS-7 "351.5"
*HW_I_OPT_ID-0 "CBO0021"
*HW_I_OPT_ID-1 "ICR0023"
*HW_I_OPT_ID-2 "ISL0021"
*HW_I_OPT_ID-3 "ISO0021"
*HW_I_OPT_ID-4 "IAD0021"
*HW_I_OPT_ID-5 "IPR0001"
*HW_I_OPT_NAME-0 "CBOユニット|CBO unit"
*HW_I_OPT_NAME-1 "標準入射光学ユニット|Standard incident optical unit"
*HW_I_OPT_NAME-2 "標準入射スリットボックス|Standard incident slit box"
*HW_I_OPT_NAME-3 "入射平行スリット|Incident parallel slit"
*HW_I_OPT_NAME-4 "長手制限スリット|Length limiting slit"
*HW_I_OPT_NAME-5 "None|None"
*HW_R_ATTENUATER_AUTOMODE "0"
*HW_R_OPT_ID-0 "RSS0021"
*HW_R_OPT_ID-1 "RCR0023"
*HW_R_OPT_ID-2 "RSO0021"
*HW_R_OPT_ID-3 "RRS0021"
*HW_R_OPT_ID-4 "ATN0021"
*HW_R_OPT_ID-5 "RFL0021"
*HW_R_OPT_ID-6 "RAD0021"
*HW_R_OPT_NAME-0 "標準受光スリットボックス1|Standard receiving slit box # 1"
*HW_R_OPT_NAME-1 "標準受光光学ユニット1|Standard receiving unit # 1"
*HW_R_OPT_NAME-2 "標準受光光学ユニット2|Standard receiving optical unit # 2"
*HW_R_OPT_NAME-3 "標準受光スリットボックス2|Standard receiving slit box # 2"
*HW_R_OPT_NAME-4 "標準アッテネータ|Standard Attenuator"
*HW_R_OPT_NAME-5 "Cu Kβ|Cu K-beta"
*HW_R_OPT_NAME-6 "調整用受光スリット|Alignment receiving slit"
*HW_SAMPLE_HOLDER_ID "SMP0023"
*HW_SAMPLE_HOLDER_NAME "標準Zステージ|Standard Z stage"
*HW_XG_CURRENT_MAX "50"
*HW_XG_CURRENT_MIN "2"
*HW_XG_CURRENT_RESOLUTION "1"
*HW_XG_CURRENT_UNIT "mA"
*HW_XG_FOCUS "1mm x 10mm"
*HW_XG_FOCUS_TYPE "Fine"
*HW_XG_ID "1200"
*HW_XG_NAME "3kW 封入管(ID:1200)|3kW Sealed tube(ID:1200)"
*HW_XG_TARGET_ATOMIC_NUMBER "29.0000000000"
*HW_XG_TARGET_NAME "Cu"
*HW_XG_TYPE "Hermetic"
*HW_XG_VOLTAGE_MAX "60"
*HW_XG_VOLTAGE_MIN "20"
*HW_XG_VOLTAGE_RESOLUTION "1"
*HW_XG_VOLTAGE_UNIT "kV"
*HW_XG_WATT_MAX "2"
*HW_XG_WATT_UNIT "kW"
*HW_XG_WAVE_LENGTH_ALPHA1 "1.540593"
*HW_XG_WAVE_LENGTH_ALPHA2 "1.544414"
*HW_XG_WAVE_LENGTH_BETA "1.392250"
*MEAS_COND_AXIS_NAME-0 "2θ/θ"
*MEAS_COND_AXIS_NAME-1 "2θ"
*MEAS_COND_AXIS_NAME-2 "ω"
*MEAS_COND_AXIS_NAME-3 "Z"
*MEAS_COND_AXIS_NAME-4 "2θ/ω"
*MEAS_COND_AXIS_NAME-5 "θs"
*MEAS_COND_AXIS_NAME-6 "θd"
*MEAS_COND_AXIS_NAME-7 "Ts"
*MEAS_COND_AXIS_NAME-8 "CBO選択スリット"
*MEAS_COND_AXIS_NAME-9 "M"
*MEAS_COND_AXIS_NAME-10 "入射平行スリット"
*MEAS_COND_AXIS_NAME-11 "入射スリット"
*MEAS_COND_AXIS_NAME-12 ""
*MEAS_COND_AXIS_NAME-13 "Zs"
*MEAS_COND_AXIS_NAME-14 "入射光学素子"
*MEAS_COND_AXIS_NAME-15 "長手制限スリット"
*MEAS_COND_AXIS_NAME-16 "センタースリット"
*MEAS_COND_AXIS_NAME-17 "フィルター"
*MEAS_COND_AXIS_NAME-18 "受光スリット1"
*MEAS_COND_AXIS_NAME-19 "受光スリット2"
*MEAS_COND_AXIS_NAME-20 "受光光学素子"
*MEAS_COND_AXIS_NAME-21 "受光平行スリット"
*MEAS_COND_AXIS_NAME-22 "調整用受光スリット"
*MEAS_COND_AXIS_NAME-23 ""
*MEAS_COND_AXIS_NAME-24 ""
*MEAS_COND_AXIS_NAME-25 "Zd"
*MEAS_COND_AXIS_NAME-26 "アッテネータ"
*MEAS_COND_AXIS_NAME-27 "検出器モノクロメータ"
*MEAS_COND_AXIS_NAME-28 "モノクロメータスリット"
*MEAS_COND_AXIS_NAME-29 "プライマリビーム"
*MEAS_COND_AXIS_NAME-30 "PHA"
*MEAS_COND_AXIS_NAME_INTERNAL-0 "TwoThetaTheta"
*MEAS_COND_AXIS_NAME_INTERNAL-1 "TwoTheta"
*MEAS_COND_AXIS_NAME_INTERNAL-2 "Omega"
*MEAS_COND_AXIS_NAME_INTERNAL-3 "Z"
*MEAS_COND_AXIS_NAME_INTERNAL-4 "TwoThetaOmega"
*MEAS_COND_AXIS_NAME_INTERNAL-5 "ThetaS"
*MEAS_COND_AXIS_NAME_INTERNAL-6 "ThetaD"
*MEAS_COND_AXIS_NAME_INTERNAL-7 "Ts"
*MEAS_COND_AXIS_NAME_INTERNAL-8 "CBO"
*MEAS_COND_AXIS_NAME_INTERNAL-9 "CBO-M"
*MEAS_COND_AXIS_NAME_INTERNAL-10 "IncidentSollerSlit"
*MEAS_COND_AXIS_NAME_INTERNAL-11 "IncidentSlitBox"
*MEAS_COND_AXIS_NAME_INTERNAL-12 "IncidentSlitBox-_Axis"
*MEAS_COND_AXIS_NAME_INTERNAL-13 "Zs"
*MEAS_COND_AXIS_NAME_INTERNAL-14 "IncidentMonochromator"
*MEAS_COND_AXIS_NAME_INTERNAL-15 "IncidentAxdSlit"
*MEAS_COND_AXIS_NAME_INTERNAL-16 "CenterSlit"
*MEAS_COND_AXIS_NAME_INTERNAL-17 "Filter"
*MEAS_COND_AXIS_NAME_INTERNAL-18 "ReceivingSlitBox1"
*MEAS_COND_AXIS_NAME_INTERNAL-19 "ReceivingSlitBox2"
*MEAS_COND_AXIS_NAME_INTERNAL-20 "ReceivingOptics"
*MEAS_COND_AXIS_NAME_INTERNAL-21 "ReceivingSollerSlit"
*MEAS_COND_AXIS_NAME_INTERNAL-22 "ReceivingAxdSlit"
*MEAS_COND_AXIS_NAME_INTERNAL-23 "ReceivingSlitBox1-_Axis"
*MEAS_COND_AXIS_NAME_INTERNAL-24 "ReceivingSlitBox2-_Axis"
*MEAS_COND_AXIS_NAME_INTERNAL-25 "ReceivingSlitBox2-Zd"
*MEAS_COND_AXIS_NAME_INTERNAL-26 "Attenuator"
*MEAS_COND_AXIS_NAME_INTERNAL-27 "CounterMonochromator"
*MEAS_COND_AXIS_NAME_INTERNAL-28 "CounterSlit"
*MEAS_COND_AXIS_NAME_INTERNAL-29 "IncidentPrimary"
*MEAS_COND_AXIS_NAME_INTERNAL-30 "PHA"
*MEAS_COND_AXIS_NAME_MAGICNO-0 "83951616.0000000000"
*MEAS_COND_AXIS_NAME_MAGICNO-1 "268632064.0000000000"
*MEAS_COND_AXIS_NAME_MAGICNO-2 "268500992.0000000000"
*MEAS_COND_AXIS_NAME_MAGICNO-3 "285278208.0000000000"
*MEAS_COND_AXIS_NAME_MAGICNO-4 "83951616.0000000000"
*MEAS_COND_AXIS_NAME_MAGICNO-5 "131072.0000000000"
*MEAS_COND_AXIS_NAME_MAGICNO-6 "131072.0000000000"
*MEAS_COND_AXIS_NAME_MAGICNO-7 "318898176.0000000000"
*MEAS_COND_AXIS_NAME_MAGICNO-8 "20971521.0000000000"
*MEAS_COND_AXIS_NAME_MAGICNO-9 "285343744.0000000000"
*MEAS_COND_AXIS_NAME_MAGICNO-10 "20971521.0000000000"
*MEAS_COND_AXIS_NAME_MAGICNO-11 "22020097.0000000000"
*MEAS_COND_AXIS_NAME_MAGICNO-12 "25165824.0000000000"
*MEAS_COND_AXIS_NAME_MAGICNO-13 "318898176.0000000000"
*MEAS_COND_AXIS_NAME_MAGICNO-14 "1.0000000000"
*MEAS_COND_AXIS_NAME_MAGICNO-15 "20971521.0000000000"
*MEAS_COND_AXIS_NAME_MAGICNO-16 "20971521.0000000000"
*MEAS_COND_AXIS_NAME_MAGICNO-17 "20971521.0000000000"
*MEAS_COND_AXIS_NAME_MAGICNO-18 "23068673.0000000000"
*MEAS_COND_AXIS_NAME_MAGICNO-19 "23068673.0000000000"
*MEAS_COND_AXIS_NAME_MAGICNO-20 "20971521.0000000000"
*MEAS_COND_AXIS_NAME_MAGICNO-21 "20971521.0000000000"
*MEAS_COND_AXIS_NAME_MAGICNO-22 "20971521.0000000000"
*MEAS_COND_AXIS_NAME_MAGICNO-23 "25165824.0000000000"
*MEAS_COND_AXIS_NAME_MAGICNO-24 "25165824.0000000000"
*MEAS_COND_AXIS_NAME_MAGICNO-25 "285343744.0000000000"
*MEAS_COND_AXIS_NAME_MAGICNO-26 "17301505.0000000000"
*MEAS_COND_AXIS_NAME_MAGICNO-27 "20971521.0000000000"
*MEAS_COND_AXIS_NAME_MAGICNO-28 "20971521.0000000000"
*MEAS_COND_AXIS_NAME_MAGICNO-29 "20971521.0000000000"
*MEAS_COND_AXIS_NAME_MAGICNO-30 "0.0000000000"
*MEAS_COND_AXIS_OFFSET-0 "-"
*MEAS_COND_AXIS_OFFSET-1 "0.0885000000"
*MEAS_COND_AXIS_OFFSET-2 "0.4456000000"
*MEAS_COND_AXIS_OFFSET-3 "-"
*MEAS_COND_AXIS_OFFSET-4 "-"
*MEAS_COND_AXIS_OFFSET-5 "0.4456000000"
*MEAS_COND_AXIS_OFFSET-6 "-0.3571000000"
*MEAS_COND_AXIS_OFFSET-7 "-"
*MEAS_COND_AXIS_OFFSET-8 "-"
*MEAS_COND_AXIS_OFFSET-9 "-"
*MEAS_COND_AXIS_OFFSET-10 "-"
*MEAS_COND_AXIS_OFFSET-11 "-"
*MEAS_COND_AXIS_OFFSET-12 "-"
*MEAS_COND_AXIS_OFFSET-13 "-"
*MEAS_COND_AXIS_OFFSET-14 "-"
*MEAS_COND_AXIS_OFFSET-15 "-"
*MEAS_COND_AXIS_OFFSET-16 "-"
*MEAS_COND_AXIS_OFFSET-17 "-"
*MEAS_COND_AXIS_OFFSET-18 "-"
*MEAS_COND_AXIS_OFFSET-19 "-"
*MEAS_COND_AXIS_OFFSET-20 "-"
*MEAS_COND_AXIS_OFFSET-21 "-"
*MEAS_COND_AXIS_OFFSET-22 "-"
*MEAS_COND_AXIS_OFFSET-23 "-"
*MEAS_COND_AXIS_OFFSET-24 "-"
*MEAS_COND_AXIS_OFFSET-25 "-"
*MEAS_COND_AXIS_OFFSET-26 "-"
*MEAS_COND_AXIS_OFFSET-27 "-"
*MEAS_COND_AXIS_OFFSET-28 "-"
*MEAS_COND_AXIS_OFFSET-29 "-"
*MEAS_COND_AXIS_OFFSET-30 "-"
*MEAS_COND_AXIS_POSITION-0 "0.0000000000"
*MEAS_COND_AXIS_POSITION-1 "0.0000000000"
*MEAS_COND_AXIS_POSITION-2 "0.0000000000"
*MEAS_COND_AXIS_POSITION-3 "-0.4618800000"
*MEAS_COND_AXIS_POSITION-4 "0.0000000000"
*MEAS_COND_AXIS_POSITION-5 "0.0000000000"
*MEAS_COND_AXIS_POSITION-6 "0.0000000000"
*MEAS_COND_AXIS_POSITION-7 "-0.3313700000"
*MEAS_COND_AXIS_POSITION-8 "BB"
*MEAS_COND_AXIS_POSITION-9 "0.0000000000"
*MEAS_COND_AXIS_POSITION-10 "Soller_slit_5.0deg"
*MEAS_COND_AXIS_POSITION-11 "1/3deg"
*MEAS_COND_AXIS_POSITION-12 "1.1044000000"
*MEAS_COND_AXIS_POSITION-13 "-0.3371900000"
*MEAS_COND_AXIS_POSITION-14 "0.0000000000"
*MEAS_COND_AXIS_POSITION-15 "10.0mm"
*MEAS_COND_AXIS_POSITION-16 "None"
*MEAS_COND_AXIS_POSITION-17 "Cu_K-beta"
*MEAS_COND_AXIS_POSITION-18 "8.000mm"
*MEAS_COND_AXIS_POSITION-19 "13.000mm"
*MEAS_COND_AXIS_POSITION-20 "No_unit"
*MEAS_COND_AXIS_POSITION-21 "Soller_slit_5.0deg"
*MEAS_COND_AXIS_POSITION-22 "None"
*MEAS_COND_AXIS_POSITION-23 "8.0000000000"
*MEAS_COND_AXIS_POSITION-24 "13.0000000000"
*MEAS_COND_AXIS_POSITION-25 "0.1009400000"
*MEAS_COND_AXIS_POSITION-26 "Open"
*MEAS_COND_AXIS_POSITION-27 "None"
*MEAS_COND_AXIS_POSITION-28 "None"
*MEAS_COND_AXIS_POSITION-29 "None"
*MEAS_COND_AXIS_POSITION-30 "36.0000000000"
*MEAS_COND_AXIS_UNIT-0 "deg"
*MEAS_COND_AXIS_UNIT-1 "deg"
*MEAS_COND_AXIS_UNIT-2 "deg"
*MEAS_COND_AXIS_UNIT-3 "mm"
*MEAS_COND_AXIS_UNIT-4 "deg"
*MEAS_COND_AXIS_UNIT-5 "deg"
*MEAS_COND_AXIS_UNIT-6 "deg"
*MEAS_COND_AXIS_UNIT-7 "mm"
*MEAS_COND_AXIS_UNIT-8 ""
*MEAS_COND_AXIS_UNIT-9 "pulse"
*MEAS_COND_AXIS_UNIT-10 ""
*MEAS_COND_AXIS_UNIT-11 ""
*MEAS_COND_AXIS_UNIT-12 "mm"
*MEAS_COND_AXIS_UNIT-13 "mm"
*MEAS_COND_AXIS_UNIT-14 ""
*MEAS_COND_AXIS_UNIT-15 ""
*MEAS_COND_AXIS_UNIT-16 ""
*MEAS_COND_AXIS_UNIT-17 ""
*MEAS_COND_AXIS_UNIT-18 ""
*MEAS_COND_AXIS_UNIT-19 ""
*MEAS_COND_AXIS_UNIT-20 ""
*MEAS_COND_AXIS_UNIT-21 ""
*MEAS_COND_AXIS_UNIT-22 ""
*MEAS_COND_AXIS_UNIT-23 "mm"
*MEAS_COND_AXIS_UNIT-24 "mm"
*MEAS_COND_AXIS_UNIT-25 "mm"
*MEAS_COND_AXIS_UNIT-26 ""
*MEAS_COND_AXIS_UNIT-27 ""
*MEAS_COND_AXIS_UNIT-28 ""
*MEAS_COND_AXIS_UNIT-29 ""
*MEAS_COND_AXIS_UNIT-30 "div"
*MEAS_COND_COUNTER_CNTLOSS_CORR "0.0000000000"
*MEAS_COND_COUNTER_PHABASE "36.0000000000"
*MEAS_COND_COUNTER_PHAWINDOW "14.0000000000"
*MEAS_COND_COUNTER_PHA_UNIT "div"
*MEAS_COND_COUNTER_TAUDIFF "2.0000000000"
*MEAS_COND_COUNTER_TAUINT "0.1000000000"
*MEAS_COND_IRRADIATION_MODE "OFF"
*MEAS_COND_IRRADIATION_WIDTH ""
*MEAS_COND_OPT_ATTR "集中法"
*MEAS_COND_OPT_NAME "@集中法"
*MEAS_COND_UNSYMMETRIC_MODE "OFF"
*MEAS_COND_XG_CURRENT "50.0000000000"
*MEAS_COND_XG_VOLTAGE "40.0000000000"
*MEAS_COND_XG_WAVE_TYPE "Ka"
*MEAS_DATA_COUNT "4001.0000000000"
*MEAS_SCAN_AXIS_X "2θ/θ"
*MEAS_SCAN_AXIS_X_INTERNAL "TwoThetaTheta"
*MEAS_SCAN_END_TIME "09/09/24 11:39:05"
*MEAS_SCAN_MODE "CONTINUOUS"
*MEAS_SCAN_MONITOR "0"
*MEAS_SCAN_RESOLUTION_X "0.0002"
*MEAS_SCAN_SPEED "10.000000"
*MEAS_SCAN_SPEED_UNIT "deg/min"
*MEAS_SCAN_SPEED_USER "10.0"
*MEAS_SCAN_START "10.0000000000"
*MEAS_SCAN_START_TIME "09/09/24 11:30:26"
*MEAS_SCAN_STEP "0.0200000000"
*MEAS_SCAN_STOP "90.0000000000"
*MEAS_SCAN_UNIT_X "deg"
*MEAS_SCAN_UNIT_Y "counts"
*RAS_HEADER_END
*RAS_INT_START
10.0000 1014.0000 1.0000
10.0600 993.0000 1.0000
10.1200 962.0000 1.0000
10.1800 1053.0000 1.0000
10.2400 1027.0000 1.0000
10.3000 1087.0000 1.0000
10.3600 1009.0000 1.0000
10.4200 1031.0000 1.0000
10.4800 1013.0000 1.0000
10.5400 1011.0000 1.0000
10.6000 957.0000 1.0000
10.6600 1033.0000 1.0000
10.7200 964.0000 1.0000
10.7800 1036.0000 1.0000
10.8400 973.0000 1.0000
10.9000 936.0000 1.0000
10.9600 970.0000 1.0000
11.0200 948.0000 1.0000
11.0800 942.0000 1.0000
11.1400 982.0000 1.0000
11.2000 935.0000 1.0000
11.2600 918.0000 1.0000
11.3200 943.0000 1.0000
11.3800 903.0000 1.0000
11.4400 963.0000 1.0000
11.5000 947.0000 1.0000
11.5600 929.0000 1.0000
11.6200 912.0000 1.0000
11.6800 923.0000 1.0000
11.7400 929.0000 1.0000
11.8000 951.0000 1.0000
11.8600 950.0000 1.0000
11.9200 869.0000 1.0000
11.9800 838.0000 1.0000
12.0400 903.0000 1.0000
12.1000 915.0000 1.0000
12.1600 927.0000 1.0000
12.2200 833.0000 1.0000
12.2800 842.0000 1.0000
12.3400 851.0000 1.0000
12.4000 891.0000 1.0000
12.4600 866.0000 1.0000
12.5200 894.0000 1.0000
12.5800 878.0000 1.0000
12.6400 865.0000 1.0000
12.7000 818.0000 1.0000
12.7600 846.0000 1.0000
12.8200 846.0000 1.0000
12.8800 817.0000 1.0000
12.9400 854.0000 1.0000
13.0000 836.0000 1.0000
13.0600 831.0000 1.0000
13.1200 824.0000 1.0000
13.1800 780.0000 1.0000
13.2400 871.0000 1.0000
13.3000 820.0000 1.0000
13.3600 847.0000 1.0000
13.4200 813.0000 1.0000
13.4800 779.0000 1.0000
13.5400 771.0000 1.0000
13.6000 817.0000 1.0000
13.6600 785.0000 1.0000
13.7200 760.0000 1.0000
13.7800 792.0000 1.0000
13.8400 764.0000 1.0000
13.9000 835.0000 1.0000
13.9600 807.0000 1.0000
14.0200 818.0000 1.0000
14.0800 746.0000 1.0000
14.1400 808.0000 1.0000
14.2000 829.0000 1.0000
14.2600 931.0000 1.0000
14.3200 894.0000 1.0000
14.3800 948.0000 1.0000
14.4400 1165.0000 1.0000
14.5000 1263.0000 1.0000
14.5600 1447.0000 1.0000
14.6200 1865.0000 1.0000
14.6800 2347.0000 1.0000
14.7400 2983.0000 1.0000
14.8000 3925.0000 1.0000
14.8600 3656.0000 1.0000
14.9200 1854.0000 1.0000
14.9800 1251.0000 1.0000
15.0400 979.0000 1.0000
15.1000 830.0000 1.0000
15.1600 810.0000 1.0000
15.2200 748.0000 1.0000
15.2800 720.0000 1.0000
15.3400 689.0000 1.0000
15.4000 680.0000 1.0000
15.4600 693.0000 1.0000
15.5200 687.0000 1.0000
15.5800 699.0000 1.0000
15.6400 721.0000 1.0000
15.7000 680.0000 1.0000
15.7600 705.0000 1.0000
15.8200 704.0000 1.0000
15.8800 664.0000 1.0000
15.9400 671.0000 1.0000
16.0000 693.0000 1.0000
16.0600 644.0000 1.0000
16.1200 666.0000 1.0000
16.1800 675.0000 1.0000
16.2400 650.0000 1.0000
16.3000 615.0000 1.0000
16.3600 620.0000 1.0000
16.4200 600.0000 1.0000
16.4800 633.0000 1.0000
16.5400 636.0000 1.0000
16.6000 592.0000 1.0000
16.6600 648.0000 1.0000
16.7200 634.0000 1.0000
16.7800 654.0000 1.0000
16.8400 618.0000 1.0000
16.9000 665.0000 1.0000
16.9600 622.0000 1.0000
17.0200 620.0000 1.0000
17.0800 609.0000 1.0000
17.1400 652.0000 1.0000
17.2000 574.0000 1.0000
17.2600 639.0000 1.0000
17.3200 582.0000 1.0000
17.3800 589.0000 1.0000
17.4400 578.0000 1.0000
17.5000 587.0000 1.0000
17.5600 592.0000 1.0000
17.6200 592.0000 1.0000
17.6800 585.0000 1.0000
17.7400 577.0000 1.0000
17.8000 585.0000 1.0000
17.8600 562.0000 1.0000
17.9200 590.0000 1.0000
17.9800 595.0000 1.0000
18.0400 572.0000 1.0000
18.1000 534.0000 1.0000
18.1600 518.0000 1.0000
18.2200 565.0000 1.0000
18.2800 549.0000 1.0000
18.3400 586.0000 1.0000
18.4000 525.0000 1.0000
18.4600 577.0000 1.0000
18.5200 554.0000 1.0000
18.5800 539.0000 1.0000
18.6400 517.0000 1.0000
18.7000 509.0000 1.0000
18.7600 543.0000 1.0000
18.8200 520.0000 1.0000
18.8800 536.0000 1.0000
18.9400 510.0000 1.0000
19.0000 496.0000 1.0000
19.0600 492.0000 1.0000
19.1200 553.0000 1.0000
19.1800 494.0000 1.0000
19.2400 496.0000 1.0000
19.3000 514.0000 1.0000
19.3600 494.0000 1.0000
19.4200 485.0000 1.0000
19.4800 506.0000 1.0000
19.5400 463.0000 1.0000
19.6000 514.0000 1.0000
19.6600 494.0000 1.0000
19.7200 509.0000 1.0000
19.7800 507.0000 1.0000
19.8400 520.0000 1.0000
19.9000 526.0000 1.0000
19.9600 515.0000 1.0000
20.0200 495.0000 1.0000
20.0800 497.0000 1.0000
20.1400 492.0000 1.0000
20.2000 477.0000 1.0000
20.2600 478.0000 1.0000
20.3200 504.0000 1.0000
20.3800 494.0000 1.0000
20.4400 504.0000 1.0000
20.5000 466.0000 1.0000
20.5600 446.0000 1.0000
20.6200 456.0000 1.0000
20.6800 481.0000 1.0000
20.7400 462.0000 1.0000
20.8000 481.0000 1.0000
20.8600 473.0000 1.0000
20.9200 491.0000 1.0000
20.9800 454.0000 1.0000
21.0400 462.0000 1.0000
21.1000 431.0000 1.0000
21.1600 427.0000 1.0000
21.2200 498.0000 1.0000
21.2800 480.0000 1.0000
21.3400 470.0000 1.0000
21.4000 478.0000 1.0000
21.4600 533.0000 1.0000
21.5200 556.0000 1.0000
21.5800 588.0000 1.0000
21.6400 702.0000 1.0000
21.7000 595.0000 1.0000
21.7600 536.0000 1.0000
21.8200 487.0000 1.0000
21.8800 468.0000 1.0000
21.9400 486.0000 1.0000
22.0000 426.0000 1.0000
22.0600 445.0000 1.0000
22.1200 439.0000 1.0000
22.1800 495.0000 1.0000
22.2400 491.0000 1.0000
22.3000 447.0000 1.0000
22.3600 452.0000 1.0000
22.4200 423.0000 1.0000
22.4800 422.0000 1.0000
22.5400 446.0000 1.0000
22.6000 421.0000 1.0000
22.6600 417.0000 1.0000
22.7200 440.0000 1.0000
22.7800 467.0000 1.0000
22.8400 454.0000 1.0000
22.9000 421.0000 1.0000
22.9600 413.0000 1.0000
23.0200 417.0000 1.0000
23.0800 425.0000 1.0000
23.1400 462.0000 1.0000
23.2000 411.0000 1.0000
23.2600 442.0000 1.0000
23.3200 407.0000 1.0000
23.3800 467.0000 1.0000
23.4400 437.0000 1.0000
23.5000 471.0000 1.0000
23.5600 515.0000 1.0000
23.6200 487.0000 1.0000
23.6800 526.0000 1.0000
23.7400 569.0000 1.0000
23.8000 665.0000 1.0000
23.8600 761.0000 1.0000
23.9200 1029.0000 1.0000
23.9800 1342.0000 1.0000
24.0400 1914.0000 1.0000
24.1000 2698.0000 1.0000
24.1600 3913.0000 1.0000
24.2200 5163.0000 1.0000
24.2800 5507.0000 1.0000
24.3400 4034.0000 1.0000
24.4000 2410.0000 1.0000
24.4600 1373.0000 1.0000
24.5200 1012.0000 1.0000
24.5800 759.0000 1.0000
24.6400 623.0000 1.0000
24.7000 543.0000 1.0000
24.7600 561.0000 1.0000
24.8200 497.0000 1.0000
24.8800 475.0000 1.0000
24.9400 457.0000 1.0000
25.0000 453.0000 1.0000
25.0600 400.0000 1.0000
25.1200 444.0000 1.0000
25.1800 404.0000 1.0000
25.2400 424.0000 1.0000
25.3000 440.0000 1.0000
25.3600 404.0000 1.0000
25.4200 403.0000 1.0000
25.4800 451.0000 1.0000
25.5400 403.0000 1.0000
25.6000 385.0000 1.0000
25.6600 441.0000 1.0000
25.7200 376.0000 1.0000
25.7800 396.0000 1.0000
25.8400 397.0000 1.0000
25.9000 366.0000 1.0000
25.9600 385.0000 1.0000
26.0200 368.0000 1.0000
26.0800 373.0000 1.0000
26.1400 375.0000 1.0000
26.2000 364.0000 1.0000
26.2600 389.0000 1.0000
26.3200 377.0000 1.0000
26.3800 364.0000 1.0000
26.4400 366.0000 1.0000
26.5000 333.0000 1.0000
26.5600 352.0000 1.0000
26.6200 349.0000 1.0000
26.6800 366.0000 1.0000
26.7400 381.0000 1.0000
26.8000 403.0000 1.0000
26.8600 386.0000 1.0000
26.9200 350.0000 1.0000
26.9800 351.0000 1.0000
27.0400 340.0000 1.0000
27.1000 335.0000 1.0000
27.1600 346.0000 1.0000
27.2200 359.0000 1.0000
27.2800 325.0000 1.0000
27.3400 347.0000 1.0000
27.4000 320.0000 1.0000
27.4600 333.0000 1.0000
27.5200 321.0000 1.0000
27.5800 358.0000 1.0000
27.6400 354.0000 1.0000
27.7000 366.0000 1.0000
27.7600 335.0000 1.0000
27.8200 316.0000 1.0000
27.8800 362.0000 1.0000
27.9400 403.0000 1.0000
28.0000 367.0000 1.0000
28.0600 407.0000 1.0000
28.1200 448.0000 1.0000
28.1800 517.0000 1.0000
28.2400 583.0000 1.0000
28.3000 752.0000 1.0000
28.3600 927.0000 1.0000
28.4200 1236.0000 1.0000
28.4800 1509.0000 1.0000
28.5400 1444.0000 1.0000
28.6000 1170.0000 1.0000
28.6600 877.0000 1.0000
28.7200 606.0000 1.0000
28.7800 534.0000 1.0000
28.8400 473.0000 1.0000
28.9000 434.0000 1.0000
28.9600 382.0000 1.0000
29.0200 378.0000 1.0000
29.0800 411.0000 1.0000
29.1400 364.0000 1.0000
29.2000 354.0000 1.0000
29.2600 360.0000 1.0000
29.3200 388.0000 1.0000
29.3800 428.0000 1.0000
29.4400 468.0000 1.0000
29.5000 562.0000 1.0000
29.5600 719.0000 1.0000
29.6200 943.0000 1.0000
29.6800 1278.0000 1.0000
29.7400 1676.0000 1.0000
29.8000 2063.0000 1.0000
29.8600 1845.0000 1.0000
29.9200 1347.0000 1.0000
29.9800 819.0000 1.0000
30.0400 657.0000 1.0000
30.1000 491.0000 1.0000
30.1600 438.0000 1.0000
30.2200 372.0000 1.0000
30.2800 366.0000 1.0000
30.3400 348.0000 1.0000
30.4000 365.0000 1.0000
30.4600 367.0000 1.0000
30.5200 416.0000 1.0000
30.5800 491.0000 1.0000
30.6400 586.0000 1.0000
30.7000 810.0000 1.0000
30.7600 859.0000 1.0000
30.8200 648.0000 1.0000
30.8800 522.0000 1.0000
30.9400 362.0000 1.0000
31.0000 330.0000 1.0000
31.0600 299.0000 1.0000
31.1200 318.0000 1.0000
31.1800 296.0000 1.0000
31.2400 296.0000 1.0000
31.3000 269.0000 1.0000
31.3600 277.0000 1.0000
31.4200 298.0000 1.0000
31.4800 285.0000 1.0000
31.5400 288.0000 1.0000
31.6000 302.0000 1.0000
31.6600 310.0000 1.0000
31.7200 309.0000 1.0000
31.7800 295.0000 1.0000
31.8400 315.0000 1.0000
31.9000 269.0000 1.0000
31.9600 307.0000 1.0000
32.0200 280.0000 1.0000
32.0800 245.0000 1.0000
32.1400 295.0000 1.0000
32.2000 253.0000 1.0000
32.2600 265.0000 1.0000
32.3200 264.0000 1.0000
32.3800 279.0000 1.0000
32.4400 258.0000 1.0000
32.5000 257.0000 1.0000
32.5600 274.0000 1.0000
32.6200 300.0000 1.0000
32.6800 277.0000 1.0000
32.7400 264.0000 1.0000
32.8000 254.0000 1.0000
32.8600 268.0000 1.0000
32.9200 265.0000 1.0000
32.9800 284.0000 1.0000
33.0400 289.0000 1.0000
33.1000 268.0000 1.0000
33.1600 269.0000 1.0000
33.2200 282.0000 1.0000
33.2800 279.0000 1.0000
33.3400 279.0000 1.0000
33.4000 281.0000 1.0000
33.4600 290.0000 1.0000
33.5200 273.0000 1.0000
33.5800 316.0000 1.0000
33.6400 303.0000 1.0000
33.7000 302.0000 1.0000
33.7600 341.0000 1.0000
33.8200 302.0000 1.0000
33.8800 362.0000 1.0000
33.9400 342.0000 1.0000
34.0000 401.0000 1.0000
34.0600 460.0000 1.0000
34.1200 556.0000 1.0000
34.1800 646.0000 1.0000
34.2400 833.0000 1.0000
34.3000 1070.0000 1.0000
34.3600 1438.0000 1.0000
34.4200 1955.0000 1.0000
34.4800 2377.0000 1.0000
34.5400 2617.0000 1.0000
34.6000 2364.0000 1.0000
34.6600 1764.0000 1.0000
34.7200 1285.0000 1.0000
34.7800 968.0000 1.0000
34.8400 732.0000 1.0000
34.9000 558.0000 1.0000
34.9600 474.0000 1.0000
35.0200 393.0000 1.0000
35.0800 362.0000 1.0000
35.1400 336.0000 1.0000
35.2000 346.0000 1.0000
35.2600 313.0000 1.0000
35.3200 321.0000 1.0000
35.3800 286.0000 1.0000
35.4400 294.0000 1.0000
35.5000 270.0000 1.0000
35.5600 287.0000 1.0000
35.6200 263.0000 1.0000
35.6800 264.0000 1.0000
35.7400 261.0000 1.0000
35.8000 278.0000 1.0000
35.8600 278.0000 1.0000
35.9200 250.0000 1.0000
35.9800 243.0000 1.0000
36.0400 247.0000 1.0000
36.1000 247.0000 1.0000
36.1600 206.0000 1.0000
36.2200 231.0000 1.0000
36.2800 276.0000 1.0000
36.3400 235.0000 1.0000
36.4000 249.0000 1.0000
36.4600 233.0000 1.0000
36.5200 238.0000 1.0000
36.5800 236.0000 1.0000
36.6400 250.0000 1.0000
36.7000 208.0000 1.0000
36.7600 227.0000 1.0000
36.8200 232.0000 1.0000
36.8800 228.0000 1.0000
36.9400 211.0000 1.0000
37.0000 239.0000 1.0000
37.0600 235.0000 1.0000
37.1200 236.0000 1.0000
37.1800 249.0000 1.0000
37.2400 246.0000 1.0000
37.3000 245.0000 1.0000
37.3600 276.0000 1.0000
37.4200 327.0000 1.0000
37.4800 302.0000 1.0000
37.5400 350.0000 1.0000
37.6000 489.0000 1.0000
37.6600 597.0000 1.0000
37.7200 587.0000 1.0000
37.7800 628.0000 1.0000
37.8400 541.0000 1.0000
37.9000 504.0000 1.0000
37.9600 395.0000 1.0000
38.0200 317.0000 1.0000
38.0800 287.0000 1.0000
38.1400 274.0000 1.0000
38.2000 245.0000 1.0000
38.2600 264.0000 1.0000
38.3200 258.0000 1.0000
38.3800 266.0000 1.0000
38.4400 227.0000 1.0000
38.5000 197.0000 1.0000
38.5600 227.0000 1.0000
38.6200 263.0000 1.0000
38.6800 240.0000 1.0000
38.7400 277.0000 1.0000
38.8000 194.0000 1.0000
38.8600 232.0000 1.0000
38.9200 234.0000 1.0000
38.9800 225.0000 1.0000
39.0400 232.0000 1.0000
39.1000 214.0000 1.0000
39.1600 242.0000 1.0000
39.2200 212.0000 1.0000
39.2800 187.0000 1.0000
39.3400 206.0000 1.0000
39.4000 228.0000 1.0000
39.4600 223.0000 1.0000
39.5200 204.0000 1.0000
39.5800 230.0000 1.0000
39.6400 225.0000 1.0000
39.7000 207.0000 1.0000
39.7600 229.0000 1.0000
39.8200 229.0000 1.0000
39.8800 233.0000 1.0000
39.9400 214.0000 1.0000
40.0000 205.0000 1.0000
40.0600 222.0000 1.0000
40.1200 220.0000 1.0000
40.1800 240.0000 1.0000
40.2400 219.0000 1.0000
40.3000 213.0000 1.0000
40.3600 212.0000 1.0000
40.4200 187.0000 1.0000
40.4800 250.0000 1.0000
40.5400 226.0000 1.0000
40.6000 227.0000 1.0000
40.6600 224.0000 1.0000
40.7200 209.0000 1.0000
40.7800 212.0000 1.0000
40.8400 256.0000 1.0000
40.9000 218.0000 1.0000
40.9600 217.0000 1.0000
41.0200 235.0000 1.0000
41.0800 219.0000 1.0000
41.1400 217.0000 1.0000
41.2000 235.0000 1.0000
41.2600 237.0000 1.0000
41.3200 246.0000 1.0000
41.3800 219.0000 1.0000
41.4400 233.0000 1.0000
41.5000 224.0000 1.0000
41.5600 238.0000 1.0000
41.6200 248.0000 1.0000
41.6800 242.0000 1.0000
41.7400 259.0000 1.0000
41.8000 254.0000 1.0000
41.8600 242.0000 1.0000
41.9200 235.0000 1.0000
41.9800 291.0000 1.0000
42.0400 339.0000 1.0000
42.1000 317.0000 1.0000
42.1600 365.0000 1.0000
42.2200 413.0000 1.0000
42.2800 508.0000 1.0000
42.3400 653.0000 1.0000
42.4000 925.0000 1.0000
42.4600 1165.0000 1.0000
42.5200 1567.0000 1.0000
42.5800 1809.0000 1.0000
42.6400 1864.0000 1.0000
42.7000 1606.0000 1.0000
42.7600 1268.0000 1.0000
42.8200 958.0000 1.0000
42.8800 727.0000 1.0000
42.9400 575.0000 1.0000
43.0000 455.0000 1.0000
43.0600 396.0000 1.0000
43.1200 336.0000 1.0000
43.1800 339.0000 1.0000
43.2400 279.0000 1.0000
43.3000 264.0000 1.0000
43.3600 265.0000 1.0000
43.4200 253.0000 1.0000
43.4800 257.0000 1.0000
43.5400 242.0000 1.0000
43.6000 250.0000 1.0000
43.6600 247.0000 1.0000
43.7200 264.0000 1.0000
43.7800 278.0000 1.0000
43.8400 256.0000 1.0000
43.9000 291.0000 1.0000
43.9600 316.0000 1.0000
44.0200 351.0000 1.0000
44.0800 285.0000 1.0000
44.1400 296.0000 1.0000
44.2000 254.0000 1.0000
44.2600 196.0000 1.0000
44.3200 238.0000 1.0000
44.3800 252.0000 1.0000
44.4400 242.0000 1.0000
44.5000 225.0000 1.0000
44.5600 262.0000 1.0000
44.6200 244.0000 1.0000
44.6800 251.0000 1.0000
44.7400 242.0000 1.0000
44.8000 267.0000 1.0000
44.8600 300.0000 1.0000
44.9200 261.0000 1.0000
44.9800 318.0000 1.0000
45.0400 403.0000 1.0000
45.1000 438.0000 1.0000
45.1600 467.0000 1.0000
45.2200 577.0000 1.0000
45.2800 680.0000 1.0000
45.3400 644.0000 1.0000
45.4000 628.0000 1.0000
45.4600 555.0000 1.0000
45.5200 474.0000 1.0000
45.5800 394.0000 1.0000
45.6400 349.0000 1.0000
45.7000 313.0000 1.0000
45.7600 281.0000 1.0000
45.8200 240.0000 1.0000
45.8800 243.0000 1.0000
45.9400 218.0000 1.0000
46.0000 262.0000 1.0000
46.0600 210.0000 1.0000
46.1200 216.0000 1.0000
46.1800 213.0000 1.0000
46.2400 221.0000 1.0000
46.3000 226.0000 1.0000
46.3600 227.0000 1.0000
46.4200 226.0000 1.0000
46.4800 215.0000 1.0000
46.5400 216.0000 1.0000
46.6000 221.0000 1.0000
46.6600 209.0000 1.0000
46.7200 230.0000 1.0000
46.7800 209.0000 1.0000
46.8400 225.0000 1.0000
46.9000 229.0000 1.0000
46.9600 218.0000 1.0000
47.0200 199.0000 1.0000
47.0800 199.0000 1.0000
47.1400 232.0000 1.0000
47.2000 195.0000 1.0000
47.2600 233.0000 1.0000
47.3200 188.0000 1.0000
47.3800 194.0000 1.0000
47.4400 203.0000 1.0000
47.5000 206.0000 1.0000
47.5600 207.0000 1.0000
47.6200 251.0000 1.0000
47.6800 214.0000 1.0000
47.7400 199.0000 1.0000
47.8000 212.0000 1.0000
47.8600 230.0000 1.0000
47.9200 230.0000 1.0000
47.9800 198.0000 1.0000
48.0400 198.0000 1.0000
48.1000 235.0000 1.0000
48.1600 200.0000 1.0000
48.2200 204.0000 1.0000
48.2800 209.0000 1.0000
48.3400 233.0000 1.0000
48.4000 227.0000 1.0000
48.4600 231.0000 1.0000
48.5200 230.0000 1.0000
48.5800 204.0000 1.0000
48.6400 222.0000 1.0000
48.7000 188.0000 1.0000
48.7600 274.0000 1.0000
48.8200 271.0000 1.0000
48.8800 260.0000 1.0000
48.9400 289.0000 1.0000
49.0000 300.0000 1.0000
49.0600 334.0000 1.0000
49.1200 355.0000 1.0000
49.1800 401.0000 1.0000
49.2400 525.0000 1.0000
49.3000 644.0000 1.0000
49.3600 776.0000 1.0000
49.4200 1050.0000 1.0000
49.4800 1304.0000 1.0000
49.5400 1617.0000 1.0000
49.6000 1669.0000 1.0000
49.6600 1532.0000 1.0000
49.7200 1304.0000 1.0000
49.7800 1037.0000 1.0000
49.8400 809.0000 1.0000
49.9000 643.0000 1.0000
49.9600 494.0000 1.0000
50.0200 423.0000 1.0000
50.0800 374.0000 1.0000
50.1400 327.0000 1.0000
50.2000 320.0000 1.0000
50.2600 296.0000 1.0000
50.3200 304.0000 1.0000
50.3800 255.0000 1.0000
50.4400 259.0000 1.0000
50.5000 257.0000 1.0000
50.5600 249.0000 1.0000
50.6200 253.0000 1.0000
50.6800 232.0000 1.0000
50.7400 239.0000 1.0000
50.8000 222.0000 1.0000
50.8600 256.0000 1.0000
50.9200 218.0000 1.0000
50.9800 224.0000 1.0000
51.0400 220.0000 1.0000
51.1000 206.0000 1.0000
51.1600 256.0000 1.0000
51.2200 219.0000 1.0000
51.2800 256.0000 1.0000
51.3400 232.0000 1.0000
51.4000 258.0000 1.0000
51.4600 270.0000 1.0000
51.5200 256.0000 1.0000
51.5800 298.0000 1.0000
51.6400 310.0000 1.0000
51.7000 341.0000 1.0000
51.7600 392.0000 1.0000
51.8200 440.0000 1.0000
51.8800 476.0000 1.0000
51.9400 574.0000 1.0000
52.0000 636.0000 1.0000
52.0600 649.0000 1.0000
52.1200 557.0000 1.0000
52.1800 523.0000 1.0000
52.2400 463.0000 1.0000
52.3000 395.0000 1.0000
52.3600 359.0000 1.0000
52.4200 268.0000 1.0000
52.4800 260.0000 1.0000
52.5400 256.0000 1.0000
52.6000 232.0000 1.0000
52.6600 261.0000 1.0000
52.7200 233.0000 1.0000
52.7800 231.0000 1.0000
52.8400 215.0000 1.0000
52.9000 220.0000 1.0000
52.9600 236.0000 1.0000
53.0200 220.0000 1.0000
53.0800 224.0000 1.0000
53.1400 212.0000 1.0000
53.2000 183.0000 1.0000
53.2600 176.0000 1.0000
53.3200 204.0000 1.0000
53.3800 214.0000 1.0000
53.4400 178.0000 1.0000
53.5000 191.0000 1.0000
53.5600 175.0000 1.0000
53.6200 207.0000 1.0000
53.6800 182.0000 1.0000
53.7400 204.0000 1.0000
53.8000 188.0000 1.0000
53.8600 174.0000 1.0000
53.9200 204.0000 1.0000
53.9800 204.0000 1.0000
54.0400 215.0000 1.0000
54.1000 193.0000 1.0000
54.1600 219.0000 1.0000
54.2200 250.0000 1.0000
54.2800 216.0000 1.0000
54.3400 213.0000 1.0000
54.4000 248.0000 1.0000
54.4600 301.0000 1.0000
54.5200 387.0000 1.0000
54.5800 377.0000 1.0000
54.6400 336.0000 1.0000
54.7000 319.0000 1.0000
54.7600 222.0000 1.0000
54.8200 241.0000 1.0000
54.8800 236.0000 1.0000
54.9400 224.0000 1.0000
55.0000 218.0000 1.0000
55.0600 233.0000 1.0000
55.1200 242.0000 1.0000
55.1800 229.0000 1.0000
55.2400 231.0000 1.0000
55.3000 276.0000 1.0000
55.3600 272.0000 1.0000
55.4200 267.0000 1.0000
55.4800 317.0000 1.0000
55.5400 362.0000 1.0000
55.6000 384.0000 1.0000
55.6600 439.0000 1.0000
55.7200 492.0000 1.0000
55.7800 542.0000 1.0000
55.8400 674.0000 1.0000
55.9000 729.0000 1.0000
55.9600 694.0000 1.0000
56.0200 661.0000 1.0000
56.0800 549.0000 1.0000
56.1400 511.0000 1.0000
56.2000 420.0000 1.0000
56.2600 371.0000 1.0000
56.3200 307.0000 1.0000
56.3800 325.0000 1.0000
56.4400 221.0000 1.0000
56.5000 270.0000 1.0000
56.5600 234.0000 1.0000
56.6200 237.0000 1.0000
56.6800 239.0000 1.0000
56.7400 204.0000 1.0000
56.8000 216.0000 1.0000
56.8600 210.0000 1.0000
56.9200 225.0000 1.0000
56.9800 216.0000 1.0000
57.0400 256.0000 1.0000
57.1000 191.0000 1.0000
57.1600 195.0000 1.0000
57.2200 203.0000 1.0000
57.2800 205.0000 1.0000
57.3400 202.0000 1.0000
57.4000 202.0000 1.0000
57.4600 209.0000 1.0000
57.5200 225.0000 1.0000
57.5800 213.0000 1.0000
57.6400 212.0000 1.0000
57.7000 214.0000 1.0000
57.7600 228.0000 1.0000
57.8200 218.0000 1.0000
57.8800 235.0000 1.0000
57.9400 260.0000 1.0000
58.0000 263.0000 1.0000
58.0600 294.0000 1.0000
58.1200 319.0000 1.0000
58.1800 319.0000 1.0000
58.2400 307.0000 1.0000
58.3000 305.0000 1.0000
58.3600 307.0000 1.0000
58.4200 272.0000 1.0000
58.4800 250.0000 1.0000
58.5400 274.0000 1.0000
58.6000 272.0000 1.0000
58.6600 303.0000 1.0000
58.7200 339.0000 1.0000
58.7800 366.0000 1.0000
58.8400 410.0000 1.0000
58.9000 411.0000 1.0000
58.9600 410.0000 1.0000
59.0200 368.0000 1.0000
59.0800 365.0000 1.0000
59.1400 309.0000 1.0000
59.2000 273.0000 1.0000
59.2600 256.0000 1.0000
59.3200 243.0000 1.0000
59.3800 263.0000 1.0000
59.4400 227.0000 1.0000
59.5000 207.0000 1.0000
59.5600 202.0000 1.0000
59.6200 224.0000 1.0000
59.6800 210.0000 1.0000
59.7400 207.0000 1.0000
59.8000 208.0000 1.0000
59.8600 201.0000 1.0000
59.9200 221.0000 1.0000
59.9800 184.0000 1.0000
60.0400 201.0000 1.0000
60.1000 193.0000 1.0000
60.1600 191.0000 1.0000
60.2200 211.0000 1.0000
60.2800 199.0000 1.0000
60.3400 187.0000 1.0000
60.4000 192.0000 1.0000
60.4600 209.0000 1.0000
60.5200 194.0000 1.0000
60.5800 209.0000 1.0000
60.6400 219.0000 1.0000
60.7000 206.0000 1.0000
60.7600 185.0000 1.0000
60.8200 214.0000 1.0000
60.8800 197.0000 1.0000
60.9400 208.0000 1.0000
61.0000 186.0000 1.0000
61.0600 214.0000 1.0000
61.1200 215.0000 1.0000
61.1800 244.0000 1.0000
61.2400 242.0000 1.0000
61.3000 243.0000 1.0000
61.3600 274.0000 1.0000
61.4200 282.0000 1.0000
61.4800 333.0000 1.0000
61.5400 350.0000 1.0000
61.6000 440.0000 1.0000
61.6600 460.0000 1.0000
61.7200 582.0000 1.0000
61.7800 649.0000 1.0000
61.8400 601.0000 1.0000
61.9000 542.0000 1.0000
61.9600 498.0000 1.0000
62.0200 414.0000 1.0000
62.0800 367.0000 1.0000
62.1400 317.0000 1.0000
62.2000 293.0000 1.0000
62.2600 290.0000 1.0000
62.3200 230.0000 1.0000
62.3800 211.0000 1.0000
62.4400 209.0000 1.0000
62.5000 206.0000 1.0000
62.5600 223.0000 1.0000
62.6200 228.0000 1.0000
62.6800 197.0000 1.0000
62.7400 222.0000 1.0000
62.8000 216.0000 1.0000
62.8600 196.0000 1.0000
62.9200 190.0000 1.0000
62.9800 213.0000 1.0000
63.0400 228.0000 1.0000
63.1000 208.0000 1.0000
63.1600 187.0000 1.0000
63.2200 208.0000 1.0000
63.2800 218.0000 1.0000
63.3400 202.0000 1.0000
63.4000 230.0000 1.0000
63.4600 258.0000 1.0000
63.5200 243.0000 1.0000
63.5800 284.0000 1.0000
63.6400 280.0000 1.0000
63.7000 284.0000 1.0000
63.7600 370.0000 1.0000
63.8200 387.0000 1.0000
63.8800 394.0000 1.0000
63.9400 399.0000 1.0000
64.0000 367.0000 1.0000
64.0600 389.0000 1.0000
64.1200 309.0000 1.0000
64.1800 293.0000 1.0000
64.2400 267.0000 1.0000
64.3000 226.0000 1.0000
64.3600 227.0000 1.0000
64.4200 245.0000 1.0000
64.4800 225.0000 1.0000
64.5400 221.0000 1.0000
64.6000 219.0000 1.0000
64.6600 203.0000 1.0000
64.7200 216.0000 1.0000
64.7800 202.0000 1.0000
64.8400 202.0000 1.0000
64.9000 186.0000 1.0000
64.9600 200.0000 1.0000
65.0200 190.0000 1.0000
65.0800 193.0000 1.0000
65.1400 190.0000 1.0000
65.2000 204.0000 1.0000
65.2600 196.0000 1.0000
65.3200 200.0000 1.0000
65.3800 225.0000 1.0000
65.4400 193.0000 1.0000
65.5000 212.0000 1.0000
65.5600 206.0000 1.0000
65.6200 192.0000 1.0000
65.6800 199.0000 1.0000
65.7400 202.0000 1.0000
65.8000 213.0000 1.0000
65.8600 174.0000 1.0000
65.9200 202.0000 1.0000
65.9800 218.0000 1.0000
66.0400 182.0000 1.0000
66.1000 215.0000 1.0000
66.1600 200.0000 1.0000
66.2200 221.0000 1.0000
66.2800 213.0000 1.0000
66.3400 197.0000 1.0000
66.4000 202.0000 1.0000
66.4600 217.0000 1.0000
66.5200 204.0000 1.0000
66.5800 242.0000 1.0000
66.6400 236.0000 1.0000
66.7000 265.0000 1.0000
66.7600 261.0000 1.0000
66.8200 259.0000 1.0000
66.8800 304.0000 1.0000
66.9400 325.0000 1.0000
67.0000 328.0000 1.0000
67.0600 412.0000 1.0000
67.1200 508.0000 1.0000
67.1800 563.0000 1.0000
67.2400 610.0000 1.0000
67.3000 710.0000 1.0000
67.3600 733.0000 1.0000
67.4200 630.0000 1.0000
67.4800 627.0000 1.0000
67.5400 519.0000 1.0000
67.6000 508.0000 1.0000
67.6600 405.0000 1.0000
67.7200 385.0000 1.0000
67.7800 343.0000 1.0000
67.8400 318.0000 1.0000
67.9000 285.0000 1.0000
67.9600 285.0000 1.0000
68.0200 257.0000 1.0000
68.0800 265.0000 1.0000
68.1400 257.0000 1.0000
68.2000 239.0000 1.0000
68.2600 264.0000 1.0000
68.3200 221.0000 1.0000
68.3800 228.0000 1.0000
68.4400 265.0000 1.0000
68.5000 247.0000 1.0000
68.5600 220.0000 1.0000
68.6200 228.0000 1.0000
68.6800 228.0000 1.0000
68.7400 199.0000 1.0000
68.8000 209.0000 1.0000
68.8600 208.0000 1.0000
68.9200 228.0000 1.0000
68.9800 237.0000 1.0000
69.0400 257.0000 1.0000
69.1000 232.0000 1.0000
69.1600 255.0000 1.0000
69.2200 252.0000 1.0000
69.2800 303.0000 1.0000
69.3400 321.0000 1.0000
69.4000 308.0000 1.0000
69.4600 328.0000 1.0000
69.5200 336.0000 1.0000
69.5800 289.0000 1.0000
69.6400 266.0000 1.0000
69.7000 231.0000 1.0000
69.7600 229.0000 1.0000
69.8200 212.0000 1.0000
69.8800 225.0000 1.0000
69.9400 205.0000 1.0000
70.0000 230.0000 1.0000
70.0600 199.0000 1.0000
70.1200 196.0000 1.0000
70.1800 185.0000 1.0000
70.2400 195.0000 1.0000
70.3000 184.0000 1.0000
70.3600 186.0000 1.0000
70.4200 206.0000 1.0000
70.4800 191.0000 1.0000
70.5400 186.0000 1.0000
70.6000 194.0000 1.0000
70.6600 185.0000 1.0000
70.7200 184.0000 1.0000
70.7800 175.0000 1.0000
70.8400 175.0000 1.0000
70.9000 181.0000 1.0000
70.9600 187.0000 1.0000
71.0200 186.0000 1.0000
71.0800 183.0000 1.0000
71.1400 187.0000 1.0000
71.2000 157.0000 1.0000
71.2600 182.0000 1.0000
71.3200 191.0000 1.0000
71.3800 188.0000 1.0000
71.4400 178.0000 1.0000
71.5000 182.0000 1.0000
71.5600 162.0000 1.0000
71.6200 185.0000 1.0000
71.6800 174.0000 1.0000
71.7400 207.0000 1.0000
71.8000 200.0000 1.0000
71.8600 207.0000 1.0000
71.9200 206.0000 1.0000
71.9800 184.0000 1.0000
72.0400 193.0000 1.0000
72.1000 207.0000 1.0000
72.1600 191.0000 1.0000
72.2200 187.0000 1.0000
72.2800 219.0000 1.0000
72.3400 246.0000 1.0000
72.4000 256.0000 1.0000
72.4600 304.0000 1.0000
72.5200 319.0000 1.0000
72.5800 278.0000 1.0000
72.6400 312.0000 1.0000
72.7000 299.0000 1.0000
72.7600 302.0000 1.0000
72.8200 305.0000 1.0000
72.8800 270.0000 1.0000
72.9400 258.0000 1.0000
73.0000 240.0000 1.0000
73.0600 233.0000 1.0000
73.1200 227.0000 1.0000
73.1800 207.0000 1.0000
73.2400 190.0000 1.0000
73.3000 204.0000 1.0000
73.3600 160.0000 1.0000
73.4200 193.0000 1.0000
73.4800 191.0000 1.0000
73.5400 201.0000 1.0000
73.6000 188.0000 1.0000
73.6600 174.0000 1.0000
73.7200 183.0000 1.0000
73.7800 192.0000 1.0000
73.8400 182.0000 1.0000
73.9000 162.0000 1.0000
73.9600 179.0000 1.0000
74.0200 193.0000 1.0000
74.0800 185.0000 1.0000
74.1400 197.0000 1.0000
74.2000 195.0000 1.0000
74.2600 201.0000 1.0000
74.3200 170.0000 1.0000
74.3800 184.0000 1.0000
74.4400 206.0000 1.0000
74.5000 199.0000 1.0000
74.5600 167.0000 1.0000
74.6200 182.0000 1.0000
74.6800 196.0000 1.0000
74.7400 195.0000 1.0000
74.8000 178.0000 1.0000
74.8600 195.0000 1.0000
74.9200 201.0000 1.0000
74.9800 176.0000 1.0000
75.0400 203.0000 1.0000
75.1000 162.0000 1.0000
75.1600 188.0000 1.0000
75.2200 175.0000 1.0000
75.2800 198.0000 1.0000
75.3400 197.0000 1.0000
75.4000 185.0000 1.0000
75.4600 199.0000 1.0000
75.5200 186.0000 1.0000
75.5800 165.0000 1.0000
75.6400 174.0000 1.0000
75.7000 166.0000 1.0000
75.7600 192.0000 1.0000
75.8200 176.0000 1.0000
75.8800 163.0000 1.0000
75.9400 185.0000 1.0000
76.0000 199.0000 1.0000
76.0600 173.0000 1.0000
76.1200 179.0000 1.0000
76.1800 151.0000 1.0000
76.2400 201.0000 1.0000
76.3000 206.0000 1.0000
76.3600 178.0000 1.0000
76.4200 182.0000 1.0000
76.4800 219.0000 1.0000
76.5400 197.0000 1.0000
76.6000 182.0000 1.0000
76.6600 189.0000 1.0000
76.7200 212.0000 1.0000
76.7800 199.0000 1.0000
76.8400 209.0000 1.0000
76.9000 221.0000 1.0000
76.9600 211.0000 1.0000
77.0200 184.0000 1.0000
77.0800 228.0000 1.0000
77.1400 208.0000 1.0000
77.2000 207.0000 1.0000
77.2600 231.0000 1.0000
77.3200 227.0000 1.0000
77.3800 242.0000 1.0000
77.4400 236.0000 1.0000
77.5000 248.0000 1.0000
77.5600 271.0000 1.0000
77.6200 288.0000 1.0000
77.6800 292.0000 1.0000
77.7400 313.0000 1.0000
77.8000 367.0000 1.0000
77.8600 342.0000 1.0000
77.9200 375.0000 1.0000
77.9800 339.0000 1.0000
78.0400 337.0000 1.0000
78.1000 328.0000 1.0000
78.1600 284.0000 1.0000
78.2200 297.0000 1.0000
78.2800 276.0000 1.0000
78.3400 277.0000 1.0000
78.4000 249.0000 1.0000
78.4600 213.0000 1.0000
78.5200 205.0000 1.0000
78.5800 216.0000 1.0000
78.6400 210.0000 1.0000
78.7000 202.0000 1.0000
78.7600 250.0000 1.0000
78.8200 200.0000 1.0000
78.8800 212.0000 1.0000
78.9400 188.0000 1.0000
79.0000 199.0000 1.0000
79.0600 203.0000 1.0000
79.1200 233.0000 1.0000
79.1800 185.0000 1.0000
79.2400 212.0000 1.0000
79.3000 202.0000 1.0000
79.3600 203.0000 1.0000
79.4200 216.0000 1.0000
79.4800 226.0000 1.0000
79.5400 238.0000 1.0000
79.6000 238.0000 1.0000
79.6600 247.0000 1.0000
79.7200 268.0000 1.0000
79.7800 296.0000 1.0000
79.8400 264.0000 1.0000
79.9000 241.0000 1.0000
79.9600 293.0000 1.0000
80.0200 244.0000 1.0000
80.0800 242.0000 1.0000
80.1400 218.0000 1.0000
80.2000 255.0000 1.0000
80.2600 248.0000 1.0000
80.3200 249.0000 1.0000
80.3800 253.0000 1.0000
80.4400 268.0000 1.0000
80.5000 251.0000 1.0000
80.5600 247.0000 1.0000
80.6200 237.0000 1.0000
80.6800 217.0000 1.0000
80.7400 251.0000 1.0000
80.8000 239.0000 1.0000
80.8600 216.0000 1.0000
80.9200 242.0000 1.0000
80.9800 246.0000 1.0000
81.0400 181.0000 1.0000
[...]
40.2400 195.0000 1.0000
40.3000 231.0000 1.0000
40.3600 233.0000 1.0000
40.4200 227.0000 1.0000
40.4800 230.0000 1.0000
40.5400 201.0000 1.0000
40.6000 223.0000 1.0000
40.6600 216.0000 1.0000
40.7200 235.0000 1.0000
40.7800 235.0000 1.0000
40.8400 236.0000 1.0000
40.9000 215.0000 1.0000
40.9600 203.0000 1.0000
41.0200 216.0000 1.0000
41.0800 225.0000 1.0000
41.1400 217.0000 1.0000
41.2000 242.0000 1.0000
41.2600 241.0000 1.0000
41.3200 209.0000 1.0000
41.3800 235.0000 1.0000
41.4400 240.0000 1.0000
41.5000 254.0000 1.0000
41.5600 252.0000 1.0000
41.6200 258.0000 1.0000
41.6800 258.0000 1.0000
41.7400 265.0000 1.0000
41.8000 272.0000 1.0000
41.8600 258.0000 1.0000
41.9200 264.0000 1.0000
41.9800 264.0000 1.0000
42.0400 263.0000 1.0000
42.1000 320.0000 1.0000
42.1600 362.0000 1.0000
42.2200 378.0000 1.0000
42.2800 493.0000 1.0000
42.3400 742.0000 1.0000
42.4000 877.0000 1.0000
42.4600 1196.0000 1.0000
42.5200 1521.0000 1.0000
42.5800 1859.0000 1.0000
42.6400 1859.0000 1.0000
42.7000 1559.0000 1.0000
42.7600 1219.0000 1.0000
42.8200 924.0000 1.0000
42.8800 661.0000 1.0000
42.9400 546.0000 1.0000
43.0000 450.0000 1.0000
43.0600 388.0000 1.0000
43.1200 329.0000 1.0000
43.1800 284.0000 1.0000
43.2400 304.0000 1.0000
43.3000 276.0000 1.0000
43.3600 276.0000 1.0000
43.4200 267.0000 1.0000
43.4800 278.0000 1.0000
43.5400 256.0000 1.0000
43.6000 254.0000 1.0000
43.6600 223.0000 1.0000
43.7200 249.0000 1.0000
43.7800 244.0000 1.0000
43.8400 254.0000 1.0000
43.9000 255.0000 1.0000
43.9600 334.0000 1.0000
44.0200 335.0000 1.0000
44.0800 270.0000 1.0000
44.1400 260.0000 1.0000
44.2000 218.0000 1.0000
44.2600 224.0000 1.0000
44.3200 230.0000 1.0000
44.3800 236.0000 1.0000
44.4400 233.0000 1.0000
44.5000 210.0000 1.0000
44.5600 221.0000 1.0000
44.6200 259.0000 1.0000
44.6800 273.0000 1.0000
44.7400 262.0000 1.0000
44.8000 261.0000 1.0000
44.8600 243.0000 1.0000
44.9200 299.0000 1.0000
44.9800 319.0000 1.0000
45.0400 362.0000 1.0000
45.1000 409.0000 1.0000
45.1600 453.0000 1.0000
45.2200 580.0000 1.0000
45.2800 690.0000 1.0000
45.3400 696.0000 1.0000
45.4000 596.0000 1.0000
45.4600 559.0000 1.0000
45.5200 418.0000 1.0000
45.5800 375.0000 1.0000
45.6400 336.0000 1.0000
45.7000 299.0000 1.0000
45.7600 265.0000 1.0000
45.8200 254.0000 1.0000
45.8800 261.0000 1.0000
45.9400 237.0000 1.0000
46.0000 255.0000 1.0000
46.0600 213.0000 1.0000
46.1200 216.0000 1.0000
46.1800 258.0000 1.0000
46.2400 197.0000 1.0000
46.3000 237.0000 1.0000
46.3600 246.0000 1.0000
46.4200 234.0000 1.0000
46.4800 208.0000 1.0000
46.5400 226.0000 1.0000
46.6000 235.0000 1.0000
46.6600 195.0000 1.0000
46.7200 216.0000 1.0000
46.7800 202.0000 1.0000
46.8400 217.0000 1.0000
46.9000 201.0000 1.0000
46.9600 230.0000 1.0000
47.0200 209.0000 1.0000
47.0800 225.0000 1.0000
47.1400 190.0000 1.0000
47.2000 196.0000 1.0000
47.2600 216.0000 1.0000
47.3200 195.0000 1.0000
47.3800 185.0000 1.0000
47.4400 205.0000 1.0000
47.5000 202.0000 1.0000
47.5600 204.0000 1.0000
47.6200 213.0000 1.0000
47.6800 217.0000 1.0000
47.7400 204.0000 1.0000
47.8000 209.0000 1.0000
47.8600 206.0000 1.0000
47.9200 226.0000 1.0000
47.9800 187.0000 1.0000
48.0400 222.0000 1.0000
48.1000 230.0000 1.0000
48.1600 192.0000 1.0000
48.2200 213.0000 1.0000
48.2800 220.0000 1.0000
48.3400 217.0000 1.0000
48.4000 248.0000 1.0000
48.4600 215.0000 1.0000
48.5200 243.0000 1.0000
48.5800 202.0000 1.0000
48.6400 262.0000 1.0000
48.7000 237.0000 1.0000
48.7600 217.0000 1.0000
48.8200 258.0000 1.0000
48.8800 275.0000 1.0000
48.9400 279.0000 1.0000
49.0000 273.0000 1.0000
49.0600 339.0000 1.0000
49.1200 353.0000 1.0000
49.1800 440.0000 1.0000
49.2400 462.0000 1.0000
49.3000 606.0000 1.0000
49.3600 831.0000 1.0000
49.4200 1032.0000 1.0000
49.4800 1340.0000 1.0000
49.5400 1569.0000 1.0000
49.6000 1598.0000 1.0000
49.6600 1462.0000 1.0000
49.7200 1319.0000 1.0000
49.7800 1006.0000 1.0000
49.8400 794.0000 1.0000
49.9000 645.0000 1.0000
49.9600 541.0000 1.0000
50.0200 387.0000 1.0000
50.0800 372.0000 1.0000
50.1400 319.0000 1.0000
50.2000 301.0000 1.0000
50.2600 304.0000 1.0000
50.3200 305.0000 1.0000
50.3800 263.0000 1.0000
50.4400 278.0000 1.0000
50.5000 253.0000 1.0000
50.5600 254.0000 1.0000
50.6200 237.0000 1.0000
50.6800 237.0000 1.0000
50.7400 260.0000 1.0000
50.8000 242.0000 1.0000
50.8600 227.0000 1.0000
50.9200 224.0000 1.0000
50.9800 228.0000 1.0000
51.0400 239.0000 1.0000
51.1000 221.0000 1.0000
51.1600 195.0000 1.0000
51.2200 223.0000 1.0000
51.2800 231.0000 1.0000
51.3400 265.0000 1.0000
51.4000 258.0000 1.0000
51.4600 246.0000 1.0000
51.5200 244.0000 1.0000
51.5800 257.0000 1.0000
51.6400 265.0000 1.0000
51.7000 311.0000 1.0000
51.7600 382.0000 1.0000
51.8200 456.0000 1.0000
51.8800 470.0000 1.0000
51.9400 596.0000 1.0000
52.0000 610.0000 1.0000
52.0600 639.0000 1.0000
52.1200 573.0000 1.0000
52.1800 497.0000 1.0000
52.2400 442.0000 1.0000
52.3000 338.0000 1.0000
52.3600 325.0000 1.0000
52.4200 307.0000 1.0000
52.4800 285.0000 1.0000
52.5400 274.0000 1.0000
52.6000 216.0000 1.0000
52.6600 232.0000 1.0000
52.7200 250.0000 1.0000
52.7800 231.0000 1.0000
52.8400 232.0000 1.0000
52.9000 212.0000 1.0000
52.9600 232.0000 1.0000
53.0200 203.0000 1.0000
53.0800 216.0000 1.0000
53.1400 203.0000 1.0000
53.2000 211.0000 1.0000
53.2600 205.0000 1.0000
53.3200 195.0000 1.0000
53.3800 201.0000 1.0000
53.4400 209.0000 1.0000
53.5000 187.0000 1.0000
53.5600 211.0000 1.0000
53.6200 230.0000 1.0000
53.6800 197.0000 1.0000
53.7400 185.0000 1.0000
53.8000 182.0000 1.0000
53.8600 180.0000 1.0000
53.9200 209.0000 1.0000
53.9800 209.0000 1.0000
54.0400 224.0000 1.0000
54.1000 208.0000 1.0000
54.1600 202.0000 1.0000
54.2200 211.0000 1.0000
54.2800 205.0000 1.0000
54.3400 224.0000 1.0000
54.4000 245.0000 1.0000
54.4600 281.0000 1.0000
54.5200 367.0000 1.0000
54.5800 413.0000 1.0000
54.6400 339.0000 1.0000
54.7000 283.0000 1.0000
54.7600 248.0000 1.0000
54.8200 258.0000 1.0000
54.8800 225.0000 1.0000
54.9400 209.0000 1.0000
55.0000 212.0000 1.0000
55.0600 214.0000 1.0000
55.1200 233.0000 1.0000
55.1800 236.0000 1.0000
55.2400 242.0000 1.0000
55.3000 245.0000 1.0000
55.3600 275.0000 1.0000
55.4200 279.0000 1.0000
55.4800 319.0000 1.0000
55.5400 309.0000 1.0000
55.6000 359.0000 1.0000
55.6600 433.0000 1.0000
55.7200 527.0000 1.0000
55.7800 540.0000 1.0000
55.8400 621.0000 1.0000
55.9000 722.0000 1.0000
55.9600 652.0000 1.0000
56.0200 599.0000 1.0000
56.0800 553.0000 1.0000
56.1400 481.0000 1.0000
56.2000 394.0000 1.0000
56.2600 355.0000 1.0000
56.3200 322.0000 1.0000
56.3800 284.0000 1.0000
56.4400 247.0000 1.0000
56.5000 270.0000 1.0000
56.5600 242.0000 1.0000
56.6200 238.0000 1.0000
56.6800 222.0000 1.0000
56.7400 225.0000 1.0000
56.8000 214.0000 1.0000
56.8600 235.0000 1.0000
56.9200 242.0000 1.0000
56.9800 202.0000 1.0000
57.0400 205.0000 1.0000
57.1000 212.0000 1.0000
57.1600 221.0000 1.0000
57.2200 229.0000 1.0000
57.2800 195.0000 1.0000
57.3400 220.0000 1.0000
57.4000 231.0000 1.0000
57.4600 209.0000 1.0000
57.5200 197.0000 1.0000
57.5800 195.0000 1.0000
57.6400 188.0000 1.0000
57.7000 192.0000 1.0000
57.7600 247.0000 1.0000
57.8200 214.0000 1.0000
57.8800 218.0000 1.0000
57.9400 249.0000 1.0000
58.0000 270.0000 1.0000
58.0600 291.0000 1.0000
58.1200 309.0000 1.0000
58.1800 297.0000 1.0000
58.2400 326.0000 1.0000
58.3000 337.0000 1.0000
58.3600 308.0000 1.0000
58.4200 272.0000 1.0000
58.4800 289.0000 1.0000
58.5400 300.0000 1.0000
58.6000 317.0000 1.0000
58.6600 330.0000 1.0000
58.7200 339.0000 1.0000
58.7800 376.0000 1.0000
58.8400 427.0000 1.0000
58.9000 426.0000 1.0000
58.9600 335.0000 1.0000
59.0200 356.0000 1.0000
59.0800 343.0000 1.0000
59.1400 287.0000 1.0000
59.2000 254.0000 1.0000
59.2600 269.0000 1.0000
59.3200 243.0000 1.0000
59.3800 220.0000 1.0000
59.4400 237.0000 1.0000
59.5000 178.0000 1.0000
59.5600 218.0000 1.0000
59.6200 207.0000 1.0000
59.6800 183.0000 1.0000
59.7400 195.0000 1.0000
59.8000 228.0000 1.0000
59.8600 200.0000 1.0000
59.9200 203.0000 1.0000
59.9800 208.0000 1.0000
60.0400 166.0000 1.0000
60.1000 187.0000 1.0000
60.1600 193.0000 1.0000
60.2200 212.0000 1.0000
60.2800 194.0000 1.0000
60.3400 204.0000 1.0000
60.4000 203.0000 1.0000
60.4600 208.0000 1.0000
60.5200 207.0000 1.0000
60.5800 183.0000 1.0000
60.6400 179.0000 1.0000
60.7000 201.0000 1.0000
60.7600 200.0000 1.0000
60.8200 214.0000 1.0000
60.8800 228.0000 1.0000
60.9400 199.0000 1.0000
61.0000 209.0000 1.0000
61.0600 189.0000 1.0000
61.1200 215.0000 1.0000
61.1800 225.0000 1.0000
61.2400 217.0000 1.0000
61.3000 241.0000 1.0000
61.3600 248.0000 1.0000
61.4200 256.0000 1.0000
61.4800 310.0000 1.0000
61.5400 343.0000 1.0000
61.6000 425.0000 1.0000
61.6600 485.0000 1.0000
61.7200 591.0000 1.0000
61.7800 656.0000 1.0000
61.8400 555.0000 1.0000
61.9000 570.0000 1.0000
61.9600 497.0000 1.0000
62.0200 402.0000 1.0000
62.0800 350.0000 1.0000
62.1400 295.0000 1.0000
62.2000 297.0000 1.0000
62.2600 277.0000 1.0000
62.3200 260.0000 1.0000
62.3800 228.0000 1.0000
62.4400 229.0000 1.0000
62.5000 212.0000 1.0000
62.5600 193.0000 1.0000
62.6200 190.0000 1.0000
62.6800 207.0000 1.0000
62.7400 224.0000 1.0000
62.8000 224.0000 1.0000
62.8600 206.0000 1.0000
62.9200 203.0000 1.0000
62.9800 225.0000 1.0000
63.0400 218.0000 1.0000
63.1000 196.0000 1.0000
63.1600 194.0000 1.0000
63.2200 199.0000 1.0000
63.2800 263.0000 1.0000
63.3400 223.0000 1.0000
63.4000 218.0000 1.0000
63.4600 274.0000 1.0000
63.5200 257.0000 1.0000
63.5800 292.0000 1.0000
63.6400 272.0000 1.0000
63.7000 313.0000 1.0000
63.7600 358.0000 1.0000
63.8200 375.0000 1.0000
63.8800 429.0000 1.0000
63.9400 408.0000 1.0000
64.0000 394.0000 1.0000
64.0600 358.0000 1.0000
64.1200 298.0000 1.0000
64.1800 286.0000 1.0000
64.2400 278.0000 1.0000
64.3000 247.0000 1.0000
64.3600 243.0000 1.0000
64.4200 206.0000 1.0000
64.4800 236.0000 1.0000
64.5400 216.0000 1.0000
64.6000 208.0000 1.0000
64.6600 213.0000 1.0000
64.7200 206.0000 1.0000
64.7800 226.0000 1.0000
64.8400 219.0000 1.0000
64.9000 228.0000 1.0000
64.9600 205.0000 1.0000
65.0200 188.0000 1.0000
65.0800 200.0000 1.0000
65.1400 170.0000 1.0000
65.2000 217.0000 1.0000
65.2600 194.0000 1.0000
65.3200 191.0000 1.0000
65.3800 187.0000 1.0000
65.4400 226.0000 1.0000
65.5000 212.0000 1.0000
65.5600 186.0000 1.0000
65.6200 188.0000 1.0000
65.6800 189.0000 1.0000
65.7400 225.0000 1.0000
65.8000 198.0000 1.0000
65.8600 200.0000 1.0000
65.9200 195.0000 1.0000
65.9800 196.0000 1.0000
66.0400 187.0000 1.0000
66.1000 210.0000 1.0000
66.1600 203.0000 1.0000
66.2200 199.0000 1.0000
66.2800 221.0000 1.0000
66.3400 192.0000 1.0000
66.4000 231.0000 1.0000
66.4600 218.0000 1.0000
66.5200 209.0000 1.0000
66.5800 272.0000 1.0000
66.6400 209.0000 1.0000
66.7000 250.0000 1.0000
66.7600 248.0000 1.0000
66.8200 271.0000 1.0000
66.8800 289.0000 1.0000
66.9400 315.0000 1.0000
67.0000 345.0000 1.0000
67.0600 437.0000 1.0000
67.1200 483.0000 1.0000
67.1800 532.0000 1.0000
67.2400 643.0000 1.0000
67.3000 723.0000 1.0000
67.3600 703.0000 1.0000
67.4200 662.0000 1.0000
67.4800 604.0000 1.0000
67.5400 562.0000 1.0000
67.6000 491.0000 1.0000
67.6600 434.0000 1.0000
67.7200 388.0000 1.0000
67.7800 333.0000 1.0000
67.8400 334.0000 1.0000
67.9000 277.0000 1.0000
67.9600 292.0000 1.0000
68.0200 262.0000 1.0000
68.0800 252.0000 1.0000
68.1400 239.0000 1.0000
68.2000 241.0000 1.0000
68.2600 207.0000 1.0000
68.3200 267.0000 1.0000
68.3800 226.0000 1.0000
68.4400 227.0000 1.0000
68.5000 232.0000 1.0000
68.5600 214.0000 1.0000
68.6200 222.0000 1.0000
68.6800 207.0000 1.0000
68.7400 202.0000 1.0000
68.8000 217.0000 1.0000
68.8600 235.0000 1.0000
68.9200 225.0000 1.0000
68.9800 246.0000 1.0000
69.0400 232.0000 1.0000
69.1000 263.0000 1.0000
69.1600 245.0000 1.0000
69.2200 272.0000 1.0000
69.2800 316.0000 1.0000
69.3400 325.0000 1.0000
69.4000 322.0000 1.0000
69.4600 325.0000 1.0000
69.5200 321.0000 1.0000
69.5800 281.0000 1.0000
69.6400 254.0000 1.0000
69.7000 246.0000 1.0000
69.7600 240.0000 1.0000
69.8200 246.0000 1.0000
69.8800 196.0000 1.0000
69.9400 223.0000 1.0000
70.0000 201.0000 1.0000
70.0600 218.0000 1.0000
70.1200 193.0000 1.0000
70.1800 184.0000 1.0000
70.2400 192.0000 1.0000
70.3000 180.0000 1.0000
70.3600 187.0000 1.0000
70.4200 194.0000 1.0000
70.4800 182.0000 1.0000
70.5400 168.0000 1.0000
70.6000 190.0000 1.0000
70.6600 165.0000 1.0000
70.7200 170.0000 1.0000
70.7800 189.0000 1.0000
70.8400 176.0000 1.0000
70.9000 180.0000 1.0000
70.9600 201.0000 1.0000
71.0200 208.0000 1.0000
71.0800 189.0000 1.0000
71.1400 178.0000 1.0000
71.2000 188.0000 1.0000
71.2600 167.0000 1.0000
71.3200 179.0000 1.0000
71.3800 168.0000 1.0000
71.4400 186.0000 1.0000
71.5000 174.0000 1.0000
71.5600 178.0000 1.0000
71.6200 183.0000 1.0000
71.6800 161.0000 1.0000
71.7400 204.0000 1.0000
71.8000 200.0000 1.0000
71.8600 191.0000 1.0000
71.9200 198.0000 1.0000
71.9800 198.0000 1.0000
72.0400 177.0000 1.0000
72.1000 192.0000 1.0000
72.1600 201.0000 1.0000
72.2200 190.0000 1.0000
72.2800 233.0000 1.0000
72.3400 218.0000 1.0000
72.4000 255.0000 1.0000
72.4600 263.0000 1.0000
72.5200 305.0000 1.0000
72.5800 331.0000 1.0000
72.6400 297.0000 1.0000
72.7000 331.0000 1.0000
72.7600 266.0000 1.0000
72.8200 297.0000 1.0000
72.8800 266.0000 1.0000
72.9400 221.0000 1.0000
73.0000 243.0000 1.0000
73.0600 233.0000 1.0000
73.1200 215.0000 1.0000
73.1800 207.0000 1.0000
73.2400 196.0000 1.0000
73.3000 181.0000 1.0000
73.3600 201.0000 1.0000
73.4200 193.0000 1.0000
73.4800 177.0000 1.0000
73.5400 206.0000 1.0000
73.6000 176.0000 1.0000
73.6600 200.0000 1.0000
73.7200 193.0000 1.0000
73.7800 178.0000 1.0000
73.8400 187.0000 1.0000
73.9000 197.0000 1.0000
73.9600 198.0000 1.0000
74.0200 169.0000 1.0000
74.0800 177.0000 1.0000
74.1400 185.0000 1.0000
74.2000 214.0000 1.0000
74.2600 171.0000 1.0000
74.3200 199.0000 1.0000
74.3800 191.0000 1.0000
74.4400 192.0000 1.0000
74.5000 178.0000 1.0000
74.5600 188.0000 1.0000
74.6200 201.0000 1.0000
74.6800 195.0000 1.0000
74.7400 180.0000 1.0000
74.8000 185.0000 1.0000
74.8600 190.0000 1.0000
74.9200 185.0000 1.0000
74.9800 173.0000 1.0000
75.0400 184.0000 1.0000
75.1000 195.0000 1.0000
75.1600 176.0000 1.0000
75.2200 181.0000 1.0000
75.2800 159.0000 1.0000
75.3400 192.0000 1.0000
75.4000 182.0000 1.0000
75.4600 192.0000 1.0000
75.5200 169.0000 1.0000
75.5800 211.0000 1.0000
75.6400 174.0000 1.0000
75.7000 160.0000 1.0000
75.7600 157.0000 1.0000
75.8200 193.0000 1.0000
75.8800 175.0000 1.0000
75.9400 183.0000 1.0000
76.0000 174.0000 1.0000
76.0600 183.0000 1.0000
76.1200 176.0000 1.0000
76.1800 181.0000 1.0000
76.2400 192.0000 1.0000
76.3000 192.0000 1.0000
76.3600 202.0000 1.0000
76.4200 191.0000 1.0000
76.4800 197.0000 1.0000
76.5400 207.0000 1.0000
76.6000 199.0000 1.0000
76.6600 215.0000 1.0000
76.7200 204.0000 1.0000
76.7800 205.0000 1.0000
76.8400 207.0000 1.0000
76.9000 182.0000 1.0000
76.9600 185.0000 1.0000
77.0200 202.0000 1.0000
77.0800 209.0000 1.0000
77.1400 190.0000 1.0000
77.2000 223.0000 1.0000
77.2600 217.0000 1.0000
77.3200 203.0000 1.0000
77.3800 218.0000 1.0000
77.4400 253.0000 1.0000
77.5000 255.0000 1.0000
77.5600 255.0000 1.0000
77.6200 275.0000 1.0000
77.6800 312.0000 1.0000
77.7400 328.0000 1.0000
77.8000 329.0000 1.0000
77.8600 335.0000 1.0000
77.9200 352.0000 1.0000
77.9800 328.0000 1.0000
78.0400 339.0000 1.0000
78.1000 326.0000 1.0000
78.1600 309.0000 1.0000
78.2200 271.0000 1.0000
78.2800 237.0000 1.0000
78.3400 291.0000 1.0000
78.4000 221.0000 1.0000
78.4600 218.0000 1.0000
78.5200 222.0000 1.0000
78.5800 199.0000 1.0000
78.6400 184.0000 1.0000
78.7000 195.0000 1.0000
78.7600 224.0000 1.0000
78.8200 223.0000 1.0000
78.8800 188.0000 1.0000
78.9400 204.0000 1.0000
79.0000 229.0000 1.0000
79.0600 194.0000 1.0000
79.1200 214.0000 1.0000
79.1800 211.0000 1.0000
79.2400 209.0000 1.0000
79.3000 234.0000 1.0000
79.3600 199.0000 1.0000
79.4200 227.0000 1.0000
79.4800 227.0000 1.0000
79.5400 247.0000 1.0000
79.6000 278.0000 1.0000
79.6600 272.0000 1.0000
79.7200 264.0000 1.0000
79.7800 262.0000 1.0000
79.8400 269.0000 1.0000
79.9000 258.0000 1.0000
79.9600 280.0000 1.0000
80.0200 264.0000 1.0000
80.0800 273.0000 1.0000
80.1400 254.0000 1.0000
80.2000 264.0000 1.0000
80.2600 236.0000 1.0000
80.3200 253.0000 1.0000
80.3800 269.0000 1.0000
80.4400 234.0000 1.0000
80.5000 228.0000 1.0000
80.5600 266.0000 1.0000
80.6200 240.0000 1.0000
80.6800 219.0000 1.0000
80.7400 224.0000 1.0000
80.8000 218.0000 1.0000
80.8600 247.0000 1.0000
80.9200 237.0000 1.0000
80.9800 217.0000 1.0000
81.0400 205.0000 1.0000
81.1000 184.0000 1.0000
81.1600 209.0000 1.0000
81.2200 203.0000 1.0000
81.2800 204.0000 1.0000
81.3400 214.0000 1.0000
81.4000 205.0000 1.0000
81.4600 210.0000 1.0000
81.5200 200.0000 1.0000
81.5800 219.0000 1.0000
81.6400 215.0000 1.0000
81.7000 204.0000 1.0000
81.7600 197.0000 1.0000
81.8200 227.0000 1.0000
81.8800 206.0000 1.0000
81.9400 231.0000 1.0000
82.0000 201.0000 1.0000
82.0600 208.0000 1.0000
82.1200 227.0000 1.0000
82.1800 204.0000 1.0000
82.2400 234.0000 1.0000
82.3000 226.0000 1.0000
82.3600 219.0000 1.0000
82.4200 255.0000 1.0000
82.4800 291.0000 1.0000
82.5400 300.0000 1.0000
82.6000 273.0000 1.0000
82.6600 296.0000 1.0000
82.7200 369.0000 1.0000
82.7800 351.0000 1.0000
82.8400 385.0000 1.0000
82.9000 415.0000 1.0000
82.9600 406.0000 1.0000
83.0200 416.0000 1.0000
83.0800 370.0000 1.0000
83.1400 403.0000 1.0000
83.2000 375.0000 1.0000
83.2600 357.0000 1.0000
83.3200 336.0000 1.0000
83.3800 324.0000 1.0000
83.4400 314.0000 1.0000
83.5000 291.0000 1.0000
83.5600 277.0000 1.0000
83.6200 248.0000 1.0000
83.6800 244.0000 1.0000
83.7400 271.0000 1.0000
83.8000 256.0000 1.0000
83.8600 222.0000 1.0000
83.9200 248.0000 1.0000
83.9800 222.0000 1.0000
84.0400 219.0000 1.0000
84.1000 227.0000 1.0000
84.1600 232.0000 1.0000
84.2200 203.0000 1.0000
84.2800 246.0000 1.0000
84.3400 203.0000 1.0000
84.4000 224.0000 1.0000
84.4600 214.0000 1.0000
84.5200 255.0000 1.0000
84.5800 234.0000 1.0000
84.6400 252.0000 1.0000
84.7000 236.0000 1.0000
84.7600 253.0000 1.0000
84.8200 277.0000 1.0000
84.8800 267.0000 1.0000
84.9400 247.0000 1.0000
85.0000 236.0000 1.0000
85.0600 265.0000 1.0000
85.1200 237.0000 1.0000
85.1800 264.0000 1.0000
85.2400 246.0000 1.0000
85.3000 245.0000 1.0000
85.3600 232.0000 1.0000
85.4200 196.0000 1.0000
85.4800 203.0000 1.0000
85.5400 209.0000 1.0000
85.6000 203.0000 1.0000
85.6600 220.0000 1.0000
85.7200 204.0000 1.0000
85.7800 187.0000 1.0000
85.8400 200.0000 1.0000
85.9000 204.0000 1.0000
85.9600 204.0000 1.0000
86.0200 205.0000 1.0000
86.0800 189.0000 1.0000
86.1400 198.0000 1.0000
86.2000 202.0000 1.0000
86.2600 201.0000 1.0000
86.3200 203.0000 1.0000
86.3800 183.0000 1.0000
86.4400 201.0000 1.0000
86.5000 212.0000 1.0000
86.5600 192.0000 1.0000
86.6200 165.0000 1.0000
86.6800 204.0000 1.0000
86.7400 205.0000 1.0000
86.8000 197.0000 1.0000
86.8600 184.0000 1.0000
86.9200 191.0000 1.0000
86.9800 214.0000 1.0000
87.0400 219.0000 1.0000
87.1000 209.0000 1.0000
87.1600 225.0000 1.0000
87.2200 220.0000 1.0000
87.2800 222.0000 1.0000
87.3400 217.0000 1.0000
87.4000 193.0000 1.0000
87.4600 234.0000 1.0000
87.5200 220.0000 1.0000
87.5800 227.0000 1.0000
87.6400 215.0000 1.0000
87.7000 215.0000 1.0000
87.7600 228.0000 1.0000
87.8200 245.0000 1.0000
87.8800 280.0000 1.0000
87.9400 262.0000 1.0000
88.0000 281.0000 1.0000
88.0600 254.0000 1.0000
88.1200 279.0000 1.0000
88.1800 283.0000 1.0000
88.2400 254.0000 1.0000
88.3000 242.0000 1.0000
88.3600 248.0000 1.0000
88.4200 220.0000 1.0000
88.4800 226.0000 1.0000
88.5400 258.0000 1.0000
88.6000 274.0000 1.0000
88.6600 264.0000 1.0000
88.7200 260.0000 1.0000
88.7800 254.0000 1.0000
88.8400 246.0000 1.0000
88.9000 230.0000 1.0000
88.9600 230.0000 1.0000
89.0200 257.0000 1.0000
89.0800 227.0000 1.0000
89.1400 229.0000 1.0000
89.2000 222.0000 1.0000
89.2600 201.0000 1.0000
89.3200 206.0000 1.0000
89.3800 236.0000 1.0000
89.4400 228.0000 1.0000
89.5000 224.0000 1.0000
89.5600 190.0000 1.0000
89.6200 220.0000 1.0000
89.6800 236.0000 1.0000
89.7400 225.0000 1.0000
89.8000 226.0000 1.0000
89.8600 252.0000 1.0000
89.9200 283.0000 1.0000
89.9800 256.0000 1.0000
90.0000 239.0000 1.0000
*RAS_INT_END
*RAS_DATA_END